Workbook

Sheet Test_Orientación
A1: TEST DE ORIENTACIÓN PARA ESPECIALIDADES EN ADMINISTRACIÓN (25 REACTIVOS)
A3: Versión Digital Autocalculable v2.0 | Evaluación de Habilidades Percibidas y Perfil Psicométrico
A5: I. FICHA DE IDENTIFICACIÓN DEL ESTUDIANTE
A6: Nombre del Estudiante:
A7: Tutor Asignado:
A9: II. INSTRUCCIONES Y ESCALA DE VALORACIÓN
A10: Indica el nivel de apoyo que necesitas para realizar cada actividad considerando tus experiencias del último año. Selecciona una opción del menú desplegable en la columna 'Respuesta (0-4 / SE)' para cada uno de los 25 reactivos.
A13: Valor | B13: Significado de la Escala Ordinal | D13: Descripción del Nivel de Autonomía
A14: 0 | B14: Dependencia Total | D14: Necesito que otra persona realice la actividad por mí.
A15: 1 | B15: Guía Paso a Paso | D15: Necesito orientación constante y detallada paso a paso.
A16: 2 | B16: Ayuda Parcial | D16: Necesito apoyo o revisión en algunas partes del proceso.
A17: 3 | B17: Autónomo | D17: La realizo sin ayuda de manera independiente.
A18: 4 | B18: Dominio Explicativo | D18: La realizo sin ayuda y puedo explicar el procedimiento a otros.
A19: SE | B19: Sin Experiencia Previa | D19: Sin experiencia suficiente para responder (No equivale a cero; dato faltante).
A21: III. CUESTIONARIO DE EVALUACIÓN DE HABILIDADES PERCIBIDAS
A22: # | B22: Especialidad Evaluada | C22: Cód. | D22: Conducta / Reactivo Observable | E22: Respuesta | F22: Significado / Interpretación
A23: 1 | B23: Mercadotecnia | C23: M01 | D23: Adapto la forma de presentar una idea según las personas que la escuchan. | E23: 4 | F23: =IF(E23="SE", "Sin experiencia previa", IF(E23=0, "0 - Dependencia total", IF(E23=1, "1 - Guía paso a paso", IF(E23=2, "2 - Ayuda parcial", IF(E23=3, "3 - Autónomo", IF(E23=4, "4 - Dominio explicativo", "")))))) -> 4 - Dominio explicativo
A24: 2 | B24: Mercadotecnia | C24: M02 | D24: Identifico patrones en las respuestas de un grupo de clientes o usuarios. | E24: 3 | F24: =IF(E24="SE", "Sin experiencia previa", IF(E24=0, "0 - Dependencia total", IF(E24=1, "1 - Guía paso a paso", IF(E24=2, "2 - Ayuda parcial", IF(E24=3, "3 - Autónomo", IF(E24=4, "4 - Dominio explicativo", "")))))) -> 3 - Autónomo
A25: 3 | B25: Mercadotecnia | C25: M04 | D25: Identifico la necesidad real que explica la elección de compra de una persona. | E25: 4 | F25: =IF(E25="SE", "Sin experiencia previa", IF(E25=0, "0 - Dependencia total", IF(E25=1, "1 - Guía paso a paso", IF(E25=2, "2 - Ayuda parcial", IF(E25=3, "3 - Autónomo", IF(E25=4, "4 - Dominio explicativo", "")))))) -> 4 - Dominio explicativo
A26: 4 | B26: Mercadotecnia | C26: M05 | D26: Comparo propuestas para reconocer qué las diferencia comercialmente de la competencia. | E26: 3 | F26: =IF(E26="SE", "Sin experiencia previa", IF(E26=0, "0 - Dependencia total", IF(E26=1, "1 - Guía paso a paso", IF(E26=2, "2 - Ayuda parcial", IF(E26=3, "3 - Autónomo", IF(E26=4, "4 - Dominio explicativo", "")))))) -> 3 - Autónomo
A27: 5 | B27: Mercadotecnia | C27: M09 | D27: Elijo el medio de comunicación o canal adecuado para las personas a quienes quiero llegar. | E27: 4 | F27: =IF(E27="SE", "Sin experiencia previa", IF(E27=0, "0 - Dependencia total", IF(E27=1, "1 - Guía paso a paso", IF(E27=2, "2 - Ayuda parcial", IF(E27=3, "3 - Autónomo", IF(E27=4, "4 - Dominio explicativo", "")))))) -> 4 - Dominio explicativo
A28: 6 | B28: Capital Humano | C28: CH01 | D28: Escucho una dificultad de un compañero sin interrumpir a quien la explica. | E28: 3 | F28: =IF(E28="SE", "Sin experiencia previa", IF(E28=0, "0 - Dependencia total", IF(E28=1, "1 - Guía paso a paso", IF(E28=2, "2 - Ayuda parcial", IF(E28=3, "3 - Autónomo", IF(E28=4, "4 - Dominio explicativo", "")))))) -> 3 - Autónomo
A29: 7 | B29: Capital Humano | C29: CH03 | D29: Asigno tareas considerando las fortalezas y habilidades de cada integrante del equipo. | E29: 3 | F29: =IF(E29="SE", "Sin experiencia previa", IF(E29=0, "0 - Dependencia total", IF(E29=1, "1 - Guía paso a paso", IF(E29=2, "2 - Ayuda parcial", IF(E29=3, "3 - Autónomo", IF(E29=4, "4 - Dominio explicativo", "")))))) -> 3 - Autónomo
A30: 8 | B30: Capital Humano | C30: CH04 | D30: Explico a un grupo cómo su participación individual contribuye a una meta común. | E30: 2 | F30: =IF(E30="SE", "Sin experiencia previa", IF(E30=0, "0 - Dependencia total", IF(E30=1, "1 - Guía paso a paso", IF(E30=2, "2 - Ayuda parcial", IF(E30=3, "3 - Autónomo", IF(E30=4, "4 - Dominio explicativo", "")))))) -> 2 - Ayuda parcial
A31: 9 | B31: Capital Humano | C31: CH06 | D31: Doy una sugerencia de mejora sobre una acción concreta con respeto y empatía. | E31: 3 | F31: =IF(E31="SE", "Sin experiencia previa", IF(E31=0, "0 - Dependencia total", IF(E31=1, "1 - Guía paso a paso", IF(E31=2, "2 - Ayuda parcial", IF(E31=3, "3 - Autónomo", IF(E31=4, "4 - Dominio explicativo", "")))))) -> 3 - Autónomo
A32: 10 | B32: Capital Humano | C32: CH10 | D32: Identifico, a partir de las opiniones de un grupo, qué factores dificultan su colaboración. | E32: 2 | F32: =IF(E32="SE", "Sin experiencia previa", IF(E32=0, "0 - Dependencia total", IF(E32=1, "1 - Guía paso a paso", IF(E32=2, "2 - Ayuda parcial", IF(E32=3, "3 - Autónomo", IF(E32=4, "4 - Dominio explicativo", "")))))) -> 2 - Ayuda parcial
A33: 11 | B33: Administración Financiera | C33: AF01 | D33: Organizo cantidades de ingresos y gastos para conocer el saldo disponible con precisión. | E33: 2 | F33: =IF(E33="SE", "Sin experiencia previa", IF(E33=0, "0 - Dependencia total", IF(E33=1, "1 - Guía paso a paso", IF(E33=2, "2 - Ayuda parcial", IF(E33=3, "3 - Autónomo", IF(E33=4, "4 - Dominio explicativo", "")))))) -> 2 - Ayuda parcial
A34: 12 | B34: Administración Financiera | C34: AF02 | D34: Calculo qué proporción o porcentaje representa una cantidad respecto de un total. | E34: 1 | F34: =IF(E34="SE", "Sin experiencia previa", IF(E34=0, "0 - Dependencia total", IF(E34=1, "1 - Guía paso a paso", IF(E34=2, "2 - Ayuda parcial", IF(E34=3, "3 - Autónomo", IF(E34=4, "4 - Dominio explicativo", "")))))) -> 1 - Guía paso a paso
... A47: 25 | B47: Emprendimiento | C47: E10 | D47: Ajusto mi estrategia después de identificar por qué un intento previo no funcionó. | E47: 3 | F47: =IF(E47="SE", "Sin experiencia previa", IF(E47=0, "0 - Dependencia total", IF(E47=1, "1 - Guía paso a paso", IF(E47=2, "2 - Ayuda parcial", IF(E47=3, "3 - Autónomo", IF(E47=4, "4 - Dominio explicativo", "")))))) -> 3 - Autónomo
A49: IV. TABULACIÓN Y RESULTADOS AUTOMÁTICOS POR ESPECIALIDAD
A50: Especialidad | B50: Puntaje Obt. | C50: Puntaje Máx. | D50: % Dominio | E50: Nivel / Diagnóstico | F50: Estado de Experiencia
A51: Mercadotecnia | B51: =SUMIF(E23:E27, "<>SE") -> 18 | C51: =COUNT(E23:E27)*4 -> 20 | D51: =IF(C51>0, B51/C51, 0) -> 0.9 | E51: =IF(D51>=0.8, "ALTO (Perfil Fuerte)", IF(D51>=0.5, "MEDIO (En Desarrollo)", "BAJO (Baja Afinidad)")) -> ALTO (Perfil Fuerte) | F51: =IF(COUNTIF(E23:E27, "SE")>=2, "⚠️ Requiere Exploración (2+ SE)", "Completo") -> Completo
A52: Capital Humano | B52: =SUMIF(E28:E32, "<>SE") -> 13 | C52: =COUNT(E28:E32)*4 -> 20 | D52: =IF(C52>0, B52/C52, 0) -> 0.65 | E52: =IF(D52>=0.8, "ALTO (Perfil Fuerte)", IF(D52>=0.5, "MEDIO (En Desarrollo)", "BAJO (Baja Afinidad)")) -> MEDIO (En Desarrollo) | F52: =IF(COUNTIF(E28:E32, "SE")>=2, "⚠️ Requiere Exploración (2+ SE)", "Completo") -> Completo
A53: Administración Financiera | B53: =SUMIF(E33:E37, "<>SE") -> 10 | C53: =COUNT(E33:E37)*4 -> 20 | D53: =IF(C53>0, B53/C53, 0) -> 0.5 | E53: =IF(D53>=0.8, "ALTO (Perfil Fuerte)", IF(D53>=0.5, "MEDIO (En Desarrollo)", "BAJO (Baja Afinidad)")) -> MEDIO (En Desarrollo) | F53: =IF(COUNTIF(E33:E37, "SE")>=2, "⚠️ Requiere Exploración (2+ SE)", "Completo") -> Completo
A54: Negocios Internacionales | B54: =SUMIF(E38:E42, "<>SE") -> 15 | C54: =COUNT(E38:E42)*4 -> 20 | D54: =IF(C54>0, B54/C54, 0) -> 0.75 | E54: =IF(D54>=0.8, "ALTO (Perfil Fuerte)", IF(D54>=0.5, "MEDIO (En Desarrollo)", "BAJO (Baja Afinidad)")) -> MEDIO (En Desarrollo) | F54: =IF(COUNTIF(E38:E42, "SE")>=2, "⚠️ Requiere Exploración (2+ SE)", "Completo") -> Completo
A55: Emprendimiento | B55: =SUMIF(E43:E47, "<>SE") -> 17 | C55: =COUNT(E43:E47)*4 -> 20 | D55: =IF(C55>0, B55/C55, 0) -> 0.85 | E55: =IF(D55>=0.8, "ALTO (Perfil Fuerte)", IF(D55>=0.5, "MEDIO (En Desarrollo)", "BAJO (Baja Afinidad)")) -> ALTO (Perfil Fuerte) | F55: =IF(COUNTIF(E43:E47, "SE")>=2, "⚠️ Requiere Exploración (2+ SE)", "Completo") -> Completo
A56: PUNTAJE GLOBAL Y PROMEDIO | B56: =SUM(B51:B55) -> 73 | C56: =SUM(C51:C55) -> 100 | D56: =IF(C56>0, B56/C56, 0) -> 0.73 | E56: Resultado General del Test
A58: V. ESPECIALIDADES RECOMENDADAS (AUTOCÁLCULO)
A59: 1ª Opción de Especialidad (Mayor Afinidad): | B59: =INDEX(A51:A55, MATCH(MAX(D51:D55), D51:D55, 0)) -> Mercadotecnia | E59: % Dominio: | F59: =MAX(D51:D55) -> 0.9
A60: 2ª Opción de Especialidad (Alternativa): | B60: =INDEX(A51:A55, MATCH(LARGE(D51:D55, 2), D51:D55, 0)) -> Emprendimiento | E60: % Dominio: | F60: =LARGE(D51:D55, 2) -> 0.85
...

Sheet Guía_Tutoría
A1: MATRIZ DE PERFILES PSICOMÉTRICOS Y REFERENCIA TUTORIAL
A2: Especialidad | B2: Modelo DISC / Cleaver | C2: Modelo Holland (RIASEC) | D2: Dominancia Cerebral (HBDI) | E2: Competencias Clave Asociadas
A3: Mercadotecnia | B3: Influencia (I) + Dominancia (D) - Alta persuasión, orientación a metas y comunicación fluida. | C3: Emprendedor - Artístico (E-A) - Creatividad aplicada, visión comercial y gusto por la expresión. | D3: Amarillo (Holístico/Creativo) - Síntesis visual, intuición de mercado y conceptualización. | E3: Adaptación comunicativa, análisis de necesidades del usuario, segmentación y diferenciación.
A4: Capital Humano | B4: Estabilidad (S) + Influencia (I) - Paciencia, escucha activa, empatía y mediación interpersonal. | C4: Social - Convencional (S-C) - Orientación al servicio, desarrollo de personas y organización. | D4: Rojo (Interpersonal/Empático) - Inteligencia emocional, facilitación grupal y comunicación. | E4: Escucha activa, mediación de conflictos, Inteligencia Emocional (EQ-i 2.0) y trabajo en equipo.
A5: Administración Financiera | B5: Cumplimiento (C) + Estabilidad (S) - Rigor analítico, precisión matemática y apego a normas. | C5: Convencional - Investigativo (C-I) - Preferencia por datos estructurados, cálculo y lógica. | D5: Azul (Analítico) + Verde (Estructurado) - Razonamiento cuantitativo y control de procesos. | E5: Presupuestación, análisis de costos, precisión numérico-contable y evaluación del riesgo.
A6: Negocios Internacionales | B6: Influencia (I) + Dominancia (D) - Flexibilidad comunicativa, empuje y visión estratégica global. | C6: Emprendedor - Social - Investigativo (E-S-I) - Visión global, negociación e interés cultural. | D6: Amarillo (Holístico) + Rojo (Interpersonal) - Adaptabilidad a entornos diversos y síntesis. | E6: Inteligencia Cultural (CQ), verificación normativa internacional, conversión cambiaria y logística.
A7: Emprendimiento | B7: Dominancia (D) + Influencia (I) - Alta tolerancia al riesgo, iniciativa y liderazgo motivacional. | C7: Emprendedor (E) - Búsqueda de oportunidades, toma de decisiones e innovación aplicada. | D7: Amarillo (Holístico/Creativo) + Azul (Analítico) - Visión de negocio y viabilidad financiera. | E7: Iniciativa aplicada, solución creativa de problemas (ICE), resiliencia y gestión de recursos.
